<robot name = "robot">
    <link name="Torso">
        <inertial>
            <origin xyz="0 1 2" rpy="0 0 0"/>
            <mass value="1" />
            <inertia ixx="100" ixy="0" ixz="0" iyy="100" iyz="0" izz="100" />
        </inertial>
        <visual>
            <origin xyz="0 1 2" rpy="0 0 0"/>
            <geometry>
                <box size="0.25 0.5 1" />
            </geometry>
            <material name="Cyan">
                <color rgba="0 1.0 1.0 1.0"/>
            </material>
        </visual>
        <collision>
            <origin xyz="0 1 2" rpy="0 0 0"/>
            <geometry>
                <box size="0.25 0.5 1" />
            </geometry>
        </collision>
    </link>
    <link name="ShoulderOne">
        <inertial>
            <origin xyz="0 0.1 0" rpy="0 0 0"/>
            <mass value="1" />
            <inertia ixx="100" ixy="0" ixz="0" iyy="100" iyz="0" izz="100" />
        </inertial>
        <visual>
            <origin xyz="0 0.1 0" rpy="0 0 0"/>
            <geometry>
                <box size="0.2 0.2 0.2" />
            </geometry>
            <material name="Cyan">
                <color rgba="0 1.0 1.0 1.0"/>
            </material>
        </visual>
        <collision>
            <origin xyz="0 0.1 0" rpy="0 0 0"/>
            <geometry>
                <box size="0.2 0.2 0.2" />
            </geometry>
        </collision>
    </link>
    <link name="ShoulderTwo">
        <inertial>
            <origin xyz="0 -0.1 0" rpy="0 0 0"/>
            <mass value="1" />
            <inertia ixx="100" ixy="0" ixz="0" iyy="100" iyz="0" izz="100" />
        </inertial>
        <visual>
            <origin xyz="0 -0.1 0" rpy="0 0 0"/>
            <geometry>
                <box size="0.2 0.2 0.2" />
            </geometry>
            <material name="Cyan">
                <color rgba="0 1.0 1.0 1.0"/>
            </material>
        </visual>
        <collision>
            <origin xyz="0 -0.1 0" rpy="0 0 0"/>
            <geometry>
                <box size="0.2 0.2 0.2" />
            </geometry>
        </collision>
    </link>
    <link name="UpperLegOne">
        <inertial>
            <origin xyz="0 0 -0.25" rpy="0 0 0"/>
            <mass value="1" />
            <inertia ixx="100" ixy="0" ixz="0" iyy="100" iyz="0" izz="100" />
        </inertial>
        <visual>
            <origin xyz="0 0 -0.25" rpy="0 0 0"/>
            <geometry>
                <box size="0.2 0.2 0.5" />
            </geometry>
            <material name="Cyan">
                <color rgba="0 1.0 1.0 1.0"/>
            </material>
        </visual>
        <collision>
            <origin xyz="0 0 -0.25" rpy="0 0 0"/>
            <geometry>
                <box size="0.2 0.2 0.5" />
            </geometry>
        </collision>
    </link>
    <link name="UpperLegTwo">
        <inertial>
            <origin xyz="0 0 -0.25" rpy="0 0 0"/>
            <mass value="1" />
            <inertia ixx="100" ixy="0" ixz="0" iyy="100" iyz="0" izz="100" />
        </inertial>
        <visual>
            <origin xyz="0 0 -0.25" rpy="0 0 0"/>
            <geometry>
                <box size="0.2 0.2 0.5" />
            </geometry>
            <material name="Cyan">
                <color rgba="0 1.0 1.0 1.0"/>
            </material>
        </visual>
        <collision>
            <origin xyz="0 0 -0.25" rpy="0 0 0"/>
            <geometry>
                <box size="0.2 0.2 0.5" />
            </geometry>
        </collision>
    </link>
    <link name="LowerLegOne">
        <inertial>
            <origin xyz="0 0 -0.2" rpy="0 0 0"/>
            <mass value="1" />
            <inertia ixx="100" ixy="0" ixz="0" iyy="100" iyz="0" izz="100" />
        </inertial>
        <visual>
            <origin xyz="0 0 -0.2" rpy="0 0 0"/>
            <geometry>
                <box size="0.2 0.2 0.4" />
            </geometry>
            <material name="Cyan">
                <color rgba="0 1.0 1.0 1.0"/>
            </material>
        </visual>
        <collision>
            <origin xyz="0 0 -0.2" rpy="0 0 0"/>
            <geometry>
                <box size="0.2 0.2 0.4" />
            </geometry>
        </collision>
    </link>
    <link name="LowerLegTwo">
        <inertial>
            <origin xyz="0 0 -0.2" rpy="0 0 0"/>
            <mass value="1" />
            <inertia ixx="100" ixy="0" ixz="0" iyy="100" iyz="0" izz="100" />
        </inertial>
        <visual>
            <origin xyz="0 0 -0.2" rpy="0 0 0"/>
            <geometry>
                <box size="0.2 0.2 0.4" />
            </geometry>
            <material name="Cyan">
                <color rgba="0 1.0 1.0 1.0"/>
            </material>
        </visual>
        <collision>
            <origin xyz="0 0 -0.2" rpy="0 0 0"/>
            <geometry>
                <box size="0.2 0.2 0.4" />
            </geometry>
        </collision>
    </link>
    <link name="ArmOne">
        <inertial>
            <origin xyz="0 0 -0.375" rpy="0 0 0"/>
            <mass value="1" />
            <inertia ixx="100" ixy="0" ixz="0" iyy="100" iyz="0" izz="100" />
        </inertial>
        <visual>
            <origin xyz="0 0 -0.375" rpy="0 0 0"/>
            <geometry>
                <box size="0.2 0.25 0.75" />
            </geometry>
            <material name="Cyan">
                <color rgba="0 1.0 1.0 1.0"/>
            </material>
        </visual>
        <collision>
            <origin xyz="0 0 -0.375" rpy="0 0 0"/>
            <geometry>
                <box size="0.2 0.25 0.75" />
            </geometry>
        </collision>
    </link>
    <link name="ArmTwo">
        <inertial>
            <origin xyz="0 0 -0.375" rpy="0 0 0"/>
            <mass value="1" />
            <inertia ixx="100" ixy="0" ixz="0" iyy="100" iyz="0" izz="100" />
        </inertial>
        <visual>
            <origin xyz="0 0 -0.375" rpy="0 0 0"/>
            <geometry>
                <box size="0.2 0.25 0.75" />
            </geometry>
            <material name="Cyan">
                <color rgba="0 1.0 1.0 1.0"/>
            </material>
        </visual>
        <collision>
            <origin xyz="0 0 -0.375" rpy="0 0 0"/>
            <geometry>
                <box size="0.2 0.25 0.75" />
            </geometry>
        </collision>
    </link>
    <link name="FootOne">
        <inertial>
            <origin xyz="0.05 0 -0.05" rpy="0 0 0"/>
            <mass value="1" />
            <inertia ixx="100" ixy="0" ixz="0" iyy="100" iyz="0" izz="100" />
        </inertial>
        <visual>
            <origin xyz="0.05 0 -0.05" rpy="0 0 0"/>
            <geometry>
                <box size="0.3 0.2 0.1" />
            </geometry>
            <material name="Cyan">
                <color rgba="0 1.0 1.0 1.0"/>
            </material>
        </visual>
        <collision>
            <origin xyz="0.05 0 -0.05" rpy="0 0 0"/>
            <geometry>
                <box size="0.3 0.2 0.1" />
            </geometry>
        </collision>
    </link>
    <link name="FootTwo">
        <inertial>
            <origin xyz="0.05 0 -0.05" rpy="0 0 0"/>
            <mass value="1" />
            <inertia ixx="100" ixy="0" ixz="0" iyy="100" iyz="0" izz="100" />
        </inertial>
        <visual>
            <origin xyz="0.05 0 -0.05" rpy="0 0 0"/>
            <geometry>
                <box size="0.3 0.2 0.1" />
            </geometry>
            <material name="Cyan">
                <color rgba="0 1.0 1.0 1.0"/>
            </material>
        </visual>
        <collision>
            <origin xyz="0.05 0 -0.05" rpy="0 0 0"/>
            <geometry>
                <box size="0.3 0.2 0.1" />
            </geometry>
        </collision>
    </link>
    <joint name="Torso_ShoulderOne" type="revolute">
       <parent link="Torso"/>
       <child  link="ShoulderOne"/>
       <origin rpy="0 0 0" xyz="0 1.25 2.2" />
     <axis xyz="0 1 0"/>
       <limit effort="0.0" lower="-3.14159" upper="3.14159" velocity="0.0"/>
    </joint>
    <joint name="Torso_ShoulderTwo" type="revolute">
       <parent link="Torso"/>
       <child  link="ShoulderTwo"/>
       <origin rpy="0 0 0" xyz="0 0.75 2.2" />
     <axis xyz="0 1 0"/>
       <limit effort="0.0" lower="-3.14159" upper="3.14159" velocity="0.0"/>
    </joint>
    <joint name="Torso_UpperLegOne" type="revolute">
       <parent link="Torso"/>
       <child  link="UpperLegOne"/>
       <origin rpy="0 0 0" xyz="0 0.875 1.5" />
     <axis xyz="0 1 0"/>
       <limit effort="0.0" lower="-3.14159" upper="3.14159" velocity="0.0"/>
    </joint>
    <joint name="Torso_UpperLegTwo" type="revolute">
       <parent link="Torso"/>
       <child  link="UpperLegTwo"/>
       <origin rpy="0 0 0" xyz="0 1.125 1.5" />
     <axis xyz="0 1 0"/>
       <limit effort="0.0" lower="-3.14159" upper="3.14159" velocity="0.0"/>
    </joint>
    <joint name="ShoulderTwo_ArmOne" type="revolute">
       <parent link="ShoulderTwo"/>
       <child  link="ArmOne"/>
       <origin rpy="0 0 0" xyz="0 -0.2 -0.1" />
     <axis xyz="1 0 0"/>
       <limit effort="0.0" lower="-3.14159" upper="3.14159" velocity="0.0"/>
    </joint>
    <joint name="ShoulderOne_ArmTwo" type="revolute">
       <parent link="ShoulderOne"/>
       <child  link="ArmTwo"/>
       <origin rpy="0 0 0" xyz="0 0.2 -0.1" />
     <axis xyz="1 0 0"/>
       <limit effort="0.0" lower="-3.14159" upper="3.14159" velocity="0.0"/>
    </joint>
    <joint name="UpperLegOne_LowerLegOne" type="revolute">
       <parent link="UpperLegOne"/>
       <child  link="LowerLegOne"/>
       <origin rpy="0 0 0" xyz="0 0 -0.5" />
     <axis xyz="0 1 0"/>
       <limit effort="0.0" lower="-3.14159" upper="3.14159" velocity="0.0"/>
    </joint>
    <joint name="UpperLegTwo_LowerLegTwo" type="revolute">
       <parent link="UpperLegTwo"/>
       <child  link="LowerLegTwo"/>
       <origin rpy="0 0 0" xyz="0 0 -0.5" />
     <axis xyz="0 1 0"/>
       <limit effort="0.0" lower="-3.14159" upper="3.14159" velocity="0.0"/>
    </joint>
    <joint name="LowerLegOne_FootOne" type="revolute">
       <parent link="LowerLegOne"/>
       <child  link="FootOne"/>
       <origin rpy="0 0 0" xyz="0 0 -0.4" />
     <axis xyz="0 1 0"/>
       <limit effort="0.0" lower="-3.14159" upper="3.14159" velocity="0.0"/>
    </joint>
    <joint name="LowerLegTwo_FootTwo" type="revolute">
       <parent link="LowerLegTwo"/>
       <child  link="FootTwo"/>
       <origin rpy="0 0 0" xyz="0 0 -0.4" />
     <axis xyz="0 1 0"/>
       <limit effort="0.0" lower="-3.14159" upper="3.14159" velocity="0.0"/>
    </joint>
</robot>